{"uuid": "2d23e87b-09ae-4c82-9ec9-3c41f2df4816", "children": ["0a858a42-4ea7-43a5-ac1c-d40360845283"], "befores": [{"name": "_Class__pytest_setup_class", "status": "broken", "statusDetails": {"message": "urllib3.exceptions.MaxRetryError: HTTPConnectionPool(host='localhost', port=4723): Max retries exceeded with url: /wd/hub/session (Caused by NewConnectionError('<urllib3.connection.HTTPConnection object at 0x00000226BDB34C18>: Failed to establish a new connection: [WinError 10061] 由于目标计算机积极拒绝，无法连接。'))\n", "trace": "  File \"C:\\Python37\\lib\\site-packages\\pluggy\\callers.py\", line 187, in _multicall\n    res = hook_impl.function(*args)\n  File \"C:\\Python37\\lib\\site-packages\\_pytest\\fixtures.py\", line 935, in pytest_fixture_setup\n    result = call_fixture_func(fixturefunc, request, kwargs)\n  File \"C:\\Python37\\lib\\site-packages\\_pytest\\fixtures.py\", line 790, in call_fixture_func\n    res = next(it)\n  File \"C:\\Python37\\lib\\site-packages\\_pytest\\python.py\", line 760, in xunit_setup_class_fixture\n    _call_with_optional_argument(func, self.obj)\n  File \"C:\\Python37\\lib\\site-packages\\_pytest\\python.py\", line 701, in _call_with_optional_argument\n    func(arg)\n  File \"C:\\Users\\pengfy\\PycharmProjects\\python_ci\\src\\testcases\\test_BT_switch.py\", line 13, in setup_class\n    cls.Action = DriverClient().Action\n  File \"C:\\Users\\pengfy\\PycharmProjects\\python_ci\\sources\\get_driver.py\", line 52, in __new__\n    driver = webdriver.Remote(host, desired_caps)\n  File \"C:\\Python37\\lib\\site-packages\\appium\\webdriver\\webdriver.py\", line 144, in __init__\n    proxy\n  File \"C:\\Python37\\lib\\site-packages\\selenium\\webdriver\\remote\\webdriver.py\", line 157, in __init__\n    self.start_session(capabilities, browser_profile)\n  File \"C:\\Python37\\lib\\site-packages\\appium\\webdriver\\webdriver.py\", line 219, in start_session\n    response = self.execute(RemoteCommand.NEW_SESSION, parameters)\n  File \"C:\\Python37\\lib\\site-packages\\selenium\\webdriver\\remote\\webdriver.py\", line 319, in execute\n    response = self.command_executor.execute(driver_command, params)\n  File \"C:\\Python37\\lib\\site-packages\\selenium\\webdriver\\remote\\remote_connection.py\", line 374, in execute\n    return self._request(command_info[0], url, body=data)\n  File \"C:\\Python37\\lib\\site-packages\\selenium\\webdriver\\remote\\remote_connection.py\", line 397, in _request\n    resp = self._conn.request(method, url, body=body, headers=headers)\n  File \"C:\\Python37\\lib\\site-packages\\urllib3\\request.py\", line 72, in request\n    **urlopen_kw)\n  File \"C:\\Python37\\lib\\site-packages\\urllib3\\request.py\", line 150, in request_encode_body\n    return self.urlopen(method, url, **extra_kw)\n  File \"C:\\Python37\\lib\\site-packages\\urllib3\\poolmanager.py\", line 323, in urlopen\n    response = conn.urlopen(method, u.request_uri, **kw)\n  File \"C:\\Python37\\lib\\site-packages\\urllib3\\connectionpool.py\", line 667, in urlopen\n    **response_kw)\n  File \"C:\\Python37\\lib\\site-packages\\urllib3\\connectionpool.py\", line 667, in urlopen\n    **response_kw)\n  File \"C:\\Python37\\lib\\site-packages\\urllib3\\connectionpool.py\", line 667, in urlopen\n    **response_kw)\n  File \"C:\\Python37\\lib\\site-packages\\urllib3\\connectionpool.py\", line 638, in urlopen\n    _stacktrace=sys.exc_info()[2])\n  File \"C:\\Python37\\lib\\site-packages\\urllib3\\util\\retry.py\", line 398, in increment\n    raise MaxRetryError(_pool, url, error or ResponseError(cause))\n"}, "start": 1563334354936, "stop": 1563334365076}], "start": 1563334354936, "stop": 1563334375248}