{"uuid": "93fa413d-1093-4194-8dcf-cd69549ee4a8", "children": ["4f238dd4-1f40-4277-8692-55c823d0b0e8"], "befores": [{"name": "_Class__pytest_setup_class", "status": "broken", "statusDetails": {"message": "urllib3.exceptions.MaxRetryError: HTTPConnectionPool(host='127.0.0.1', port=4000): Max retries exceeded with url: /wd/hub/session (Caused by NewConnectionError('<urllib3.connection.HTTPConnection object at 0x0000000004162908>: Failed to establish a new connection: [WinError 10061] 由于目标计算机积极拒绝，无法连接。'))\n", "trace": "  File \"D:\\Program Files\\Python3\\lib\\site-packages\\pluggy\\callers.py\", line 187, in _multicall\n    res = hook_impl.function(*args)\n  File \"D:\\Program Files\\Python3\\lib\\site-packages\\_pytest\\fixtures.py\", line 935, in pytest_fixture_setup\n    result = call_fixture_func(fixturefunc, request, kwargs)\n  File \"D:\\Program Files\\Python3\\lib\\site-packages\\_pytest\\fixtures.py\", line 790, in call_fixture_func\n    res = next(it)\n  File \"D:\\Program Files\\Python3\\lib\\site-packages\\_pytest\\python.py\", line 760, in xunit_setup_class_fixture\n    _call_with_optional_argument(func, self.obj)\n  File \"D:\\Program Files\\Python3\\lib\\site-packages\\_pytest\\python.py\", line 701, in _call_with_optional_argument\n    func(arg)\n  File \"D:\\PycharmProject\\python_CI_demo\\src\\testcases\\test_settings.py\", line 20, in setup_class\n    cls.Action = DriverClient().Action\n  File \"D:\\PycharmProject\\python_CI_demo\\sources\\get_driver.py\", line 57, in __new__\n    driver = webdriver.Remote(host, desired_caps)\n  File \"D:\\Program Files\\Python3\\lib\\site-packages\\appium\\webdriver\\webdriver.py\", line 144, in __init__\n    proxy\n  File \"D:\\Program Files\\Python3\\lib\\site-packages\\selenium\\webdriver\\remote\\webdriver.py\", line 157, in __init__\n    self.start_session(capabilities, browser_profile)\n  File \"D:\\Program Files\\Python3\\lib\\site-packages\\appium\\webdriver\\webdriver.py\", line 219, in start_session\n    response = self.execute(RemoteCommand.NEW_SESSION, parameters)\n  File \"D:\\Program Files\\Python3\\lib\\site-packages\\selenium\\webdriver\\remote\\webdriver.py\", line 319, in execute\n    response = self.command_executor.execute(driver_command, params)\n  File \"D:\\Program Files\\Python3\\lib\\site-packages\\selenium\\webdriver\\remote\\remote_connection.py\", line 374, in execute\n    return self._request(command_info[0], url, body=data)\n  File \"D:\\Program Files\\Python3\\lib\\site-packages\\selenium\\webdriver\\remote\\remote_connection.py\", line 397, in _request\n    resp = self._conn.request(method, url, body=body, headers=headers)\n  File \"D:\\Program Files\\Python3\\lib\\site-packages\\urllib3\\request.py\", line 72, in request\n    **urlopen_kw)\n  File \"D:\\Program Files\\Python3\\lib\\site-packages\\urllib3\\request.py\", line 150, in request_encode_body\n    return self.urlopen(method, url, **extra_kw)\n  File \"D:\\Program Files\\Python3\\lib\\site-packages\\urllib3\\poolmanager.py\", line 326, in urlopen\n    response = conn.urlopen(method, u.request_uri, **kw)\n  File \"D:\\Program Files\\Python3\\lib\\site-packages\\urllib3\\connectionpool.py\", line 670, in urlopen\n    **response_kw)\n  File \"D:\\Program Files\\Python3\\lib\\site-packages\\urllib3\\connectionpool.py\", line 670, in urlopen\n    **response_kw)\n  File \"D:\\Program Files\\Python3\\lib\\site-packages\\urllib3\\connectionpool.py\", line 670, in urlopen\n    **response_kw)\n  File \"D:\\Program Files\\Python3\\lib\\site-packages\\urllib3\\connectionpool.py\", line 641, in urlopen\n    _stacktrace=sys.exc_info()[2])\n  File \"D:\\Program Files\\Python3\\lib\\site-packages\\urllib3\\util\\retry.py\", line 399, in increment\n    raise MaxRetryError(_pool, url, error or ResponseError(cause))\n"}, "start": 1564541683986, "stop": 1564541689412}], "start": 1564541683986, "stop": 1564541695475}